Workbook

Sheet ASTM D638-Probetas
A1: ASTM D638
A2: Probetas | B2: Type I | C2: Type II | D2: Type III | E2: Type IV | F2: Type V | H2: Thickness | I2: 3.2
A3: Width | B3: 13 | C3: 6 | D3: 19 | E3: 6 | F3: 3.18
A4: Length | B4: 57 | C4: 57 | D4: 57 | E4: 33 | F4: 9.53
A5: Thickness | B5: 4 | C5: 4 | D5: 7 | E5: =$H$26 -> 3.2 | F5: =$H$26 -> 3.2
A6: Seccion | B6: =B3*B5 -> 52 | C6: =C3*C5 -> 24 | D6: =D3*D5 -> 133 | E6: =E3*E5 -> 19.2 | F6: =F3*F5 -> 10.176
G26: Thickness | H26: 3.2

Sheet Plásticos
A2: NORMAS | H2: 1 [MPA] = 0.1019716212978 [kg/mm2] = 1[N/mm2] | S2: [mm] extras al | T2: MP
A3: ISO 527 | B3: Valores mecánicos de diferentes plásticos | H3: 1 | Q3: =12*9 -> 108 | S3: gauge para toma | T3: =T7*T7*3/4/1000000 -> 62.819328
A4: ASTM D638 | B4: Se tomarán de cada datasheets los valores máximos | G4: =9*1.33333 -> 11.99997 | K4: Tiempo de ensayo [min] | Q4: (1% of strain) Class C | S4: 10 | T4: =108/4/3 -> 9
A5: ASTM D882 | F5: Deformacion a la rotura | K5: Probeta tipo V | N5: Probeta tipo I,II,II,IV | Q5: extensometer | R5: Long. final | S5: Plano vertical | T5: Tamaño del | U5: Cumple el | V5: Cant. de
C6: Tensión | G6: Fuerza de Traccion [kg] | J6: [mm] traccionado en Tipo I | K6: Tiempo a 1[mm/min] | L6: Tiempo a 10[mm/min] | M6: Tiempo a 100[mm/min] | N6: Tiempo a 5mm/min | O6: Tiempo a 50[mm/min] | P6: Tiempo a 500[mm/min] | Q6: Def. Máx de Máq. | R6: Gauge | S6: toma cámara | T6: pxel [mm] | U6: extens. | V6: pixels en
A7: Marca | B7: Material | C7: [MPA] | D7: Probeta | E7: E [MPA] | F7: e [%] | G7: Tipo I | H7: Tipo II | I7: Tipo III | Q7: 1% e [mm] | T7: 9152 | U7: Clase C? | V7: ese 1%
A8: Grilon 3 | B8: PLA (ingeo) | C8: 60 | E8: 524 | F8: 6 | G8: =$C8*$H$3*'ASTM D638-Probetas'!B$6 -> 3120 | H8: =$C8*$H$3*'ASTM D638-Probetas'!C$6 -> 1440 | I8: =$C8*$H$3*'ASTM D638-Probetas'!D$6 -> 7980 | J8: =F8/100*50 -> 3 | K8: =J8/1/50*7.62 -> 0.4572 | L8: =J8/10/50*7.62 -> 0.04572 | M8: =J8/100/50*7.62 -> 0.004572 | N8: =J8/5 -> 0.6 | O8: =J8/50 -> 0.06 | P8: =J8/500 -> 0.006 | Q8: =F8*50/100/100 -> 0.03 | R8: =50+J8 -> 53 | S8: =R8+$S$4 -> 63 | T8: =S8/$T$7 -> 0.0068837413 | U8: =IF(T8<Q8,"SI",IF(Q8=0,"SI",IF(T8>Q8,"NO"))) -> SI | V8: =Q8/T8 -> 4.3580952
B9: PLA 850 (ingeo) | C9: 51 | F9: 3.3 | G9: =$C9*$H$3*'ASTM D638-Probetas'!B$6 -> 2652 | H9: =$C9*$H$3*'ASTM D638-Probetas'!C$6 -> 1224 | I9: =$C9*$H$3*'ASTM D638-Probetas'!D$6 -> 6783 | J9: =F9/100*50 -> 1.65 | K9: =J9/1/50*7.62 -> 0.25146 | L9: =J9/10/50*7.62 -> 0.025146 | M9: =J9/100/50*7.62 -> 0.0025146 | N9: =J9/5 -> 0.33 | O9: =J9/50 -> 0.033 | P9: =J9/500 -> 0.0033 | Q9: =F9*50/100/100 -> 0.0165 | R9: =50+J9 -> 51.65 | S9: =R9+$S$4 -> 61.65 | T9: =S9/$T$7 -> 0.0067362325 | U9: =IF(T9<Q9,"SI",IF(Q9=0,"SI",IF(T9>Q9,"NO"))) -> SI | V9: =Q9/T9 -> 2.4494404
B10: PLA 870 (ingeo) | C10: 40 | E10: 416 | G10: =$C10*$H$3*'ASTM D638-Probetas'!B$6 -> 2080 | H10: =$C10*$H$3*'ASTM D638-Probetas'!C$6 -> 960 | I10: =$C10*$H$3*'ASTM D638-Probetas'!D$6 -> 5320 | J10: =F10/100*50 -> 0 | K10: =J10/1/50*7.62 -> 0 | L10: =J10/10/50*7.62 -> 0 | M10: =J10/100/50*7.62 -> 0 | N10: =J10/5 -> 0 | O10: =J10/50 -> 0 | P10: =J10/500 -> 0 | Q10: =F10*50/100/100 -> 0 | R10: =50+J10 -> 50 | S10: =R10+$S$4 -> 60 | T10: =S10/$T$7 -> 0.0065559441 | U10: =IF(T10<Q10,"SI",IF(Q10=0,"SI",IF(T10>Q10,"NO"))) -> SI | V10: =Q10/T10 -> 0
B11: ABS | C11: 47.56 | F11: 15 | G11: =$C11*$H$3*'ASTM D638-Probetas'!B$6 -> 2473.12 | H11: =$C11*$H$3*'ASTM D638-Probetas'!C$6 -> 1141.44 | I11: =$C11*$H$3*'ASTM D638-Probetas'!D$6 -> 6325.48 | J11: =F11/100*50 -> 7.5 | K11: =J11/1/50*7.62 -> 1.143 | L11: =J11/10/50*7.62 -> 0.1143 | M11: =J11/100/50*7.62 -> 0.01143 | N11: =J11/5 -> 1.5 | O11: =J11/50 -> 0.15 | P11: =J11/500 -> 0.015 | Q11: =F11*50/100/100 -> 0.075 | R11: =50+J11 -> 57.5 | S11: =R11+$S$4 -> 67.5 | T11: =S11/$T$7 -> 0.0073754371 | U11: =IF(T11<Q11,"SI",IF(Q11=0,"SI",IF(T11>Q11,"NO"))) -> SI | V11: =Q11/T11 -> 10.168889
B12: PETG | C12: 53 | F12: 130 | G12: =$C12*$H$3*'ASTM D638-Probetas'!B$6 -> 2756 | H12: =$C12*$H$3*'ASTM D638-Probetas'!C$6 -> 1272 | I12: =$C12*$H$3*'ASTM D638-Probetas'!D$6 -> 7049 | J12: =F12/100*50 -> 65 | K12: =J12/1/50*7.62 -> 9.906 | L12: =J12/10/50*7.62 -> 0.9906 | M12: =J12/100/50*7.62 -> 0.09906 | N12: =J12/5 -> 13 | O12: =J12/50 -> 1.3 | P12: =J12/500 -> 0.13 | Q12: =F12*50/100/100 -> 0.65 | R12: =50+J12 -> 115 | S12: =R12+$S$4 -> 125 | T12: =S12/$T$7 -> 0.013658217 | U12: =IF(T12<Q12,"SI",IF(Q12=0,"SI",IF(T12>Q12,"NO"))) -> SI | V12: =Q12/T12 -> 47.5904
B13: NYLON 12 (Grilon EMS) | C13: 55 | E13: 1400 | F13: 50 | G13: =$C13*$H$3*'ASTM D638-Probetas'!B$6 -> 2860 | H13: =$C13*$H$3*'ASTM D638-Probetas'!C$6 -> 1320 | I13: =$C13*$H$3*'ASTM D638-Probetas'!D$6 -> 7315 | J13: =F13/100*50 -> 25 | K13: =J13/1/50*7.62 -> 3.81 | L13: =J13/10/50*7.62 -> 0.381 | M13: =J13/100/50*7.62 -> 0.0381 | N13: =J13/5 -> 5 | O13: =J13/50 -> 0.5 | P13: =J13/500 -> 0.05 | Q13: =F13*50/100/100 -> 0.25 | R13: =50+J13 -> 75 | S13: =R13+$S$4 -> 85 | T13: =S13/$T$7 -> 0.0092875874 | U13: =IF(T13<Q13,"SI",IF(Q13=0,"SI",IF(T13>Q13,"NO"))) -> SI | V13: =Q13/T13 -> 26.917647
B14: ACETAL | C14: 45 | E14: 1700 | F14: 50 | G14: =$C14*$H$3*'ASTM D638-Probetas'!B$6 -> 2340 | H14: =$C14*$H$3*'ASTM D638-Probetas'!C$6 -> 1080 | I14: =$C14*$H$3*'ASTM D638-Probetas'!D$6 -> 5985 | J14: =F14/100*50 -> 25 | K14: =J14/1/50*7.62 -> 3.81 | L14: =J14/10/50*7.62 -> 0.381 | M14: =J14/100/50*7.62 -> 0.0381 | N14: =J14/5 -> 5 | O14: =J14/50 -> 0.5 | P14: =J14/500 -> 0.05 | Q14: =F14*50/100/100 -> 0.25 | R14: =50+J14 -> 75 | S14: =R14+$S$4 -> 85 | T14: =S14/$T$7 -> 0.0092875874 | U14: =IF(T14<Q14,"SI",IF(Q14=0,"SI",IF(T14>Q14,"NO"))) -> SI | V14: =Q14/T14 -> 26.917647
B15: HIPS | C15: 17 | E15: 1350 | F15: 50 | G15: =$C15*$H$3*'ASTM D638-Probetas'!B$6 -> 884 | H15: =$C15*$H$3*'ASTM D638-Probetas'!C$6 -> 408 | I15: =$C15*$H$3*'ASTM D638-Probetas'!D$6 -> 2261 | J15: =F15/100*50 -> 25 | K15: =J15/1/50*7.62 -> 3.81 | L15: =J15/10/50*7.62 -> 0.381 | M15: =J15/100/50*7.62 -> 0.0381 | N15: =J15/5 -> 5 | O15: =J15/50 -> 0.5 | P15: =J15/500 -> 0.05 | Q15: =F15*50/100/100 -> 0.25 | R15: =50+J15 -> 75 | S15: =R15+$S$4 -> 85 | T15: =S15/$T$7 -> 0.0092875874 | U15: =IF(T15<Q15,"SI",IF(Q15=0,"SI",IF(T15>Q15,"NO"))) -> SI | V15: =Q15/T15 -> 26.917647
A16: Printalot | B16: PLA | C16: 53 | E16: 3600 | F16: 6 | G16: =$C16*$H$3*'ASTM D638-Probetas'!B$6 -> 2756 | H16: =$C16*$H$3*'ASTM D638-Probetas'!C$6 -> 1272 | I16: =$C16*$H$3*'ASTM D638-Probetas'!D$6 -> 7049 | J16: =F16/100*50 -> 3 | K16: =J16/1/50*7.62 -> 0.4572 | L16: =J16/10/50*7.62 -> 0.04572 | M16: =J16/100/50*7.62 -> 0.004572 | N16: =J16/5 -> 0.6 | O16: =J16/50 -> 0.06 | P16: =J16/500 -> 0.006 | Q16: =F16*50/100/100 -> 0.03 | R16: =50+J16 -> 53 | S16: =R16+$S$4 -> 63 | T16: =S16/$T$7 -> 0.0068837413 | U16: =IF(T16<Q16,"SI",IF(Q16=0,"SI",IF(T16>Q16,"NO"))) -> SI | V16: =Q16/T16 -> 4.3580952
B17: PLA 3Di | C17: 51 | E17: 2315 | F17: 3.31 | G17: =$C17*$H$3*'ASTM D638-Probetas'!B$6 -> 2652 | H17: =$C17*$H$3*'ASTM D638-Probetas'!C$6 -> 1224 | I17: =$C17*$H$3*'ASTM D638-Probetas'!D$6 -> 6783 | J17: =F17/100*50 -> 1.655 | K17: =J17/1/50*7.62 -> 0.252222 | L17: =J17/10/50*7.62 -> 0.0252222 | M17: =J17/100/50*7.62 -> 0.00252222 | N17: =J17/5 -> 0.331 | O17: =J17/50 -> 0.0331 | P17: =J17/500 -> 0.00331 | Q17: =F17*50/100/100 -> 0.01655 | R17: =50+J17 -> 51.655 | S17: =R17+$S$4 -> 61.655 | T17: =S17/$T$7 -> 0.0067367788 | U17: =IF(T17<Q17,"SI",IF(Q17=0,"SI",IF(T17>Q17,"NO"))) -> SI | V17: =Q17/T17 -> 2.4566637
B18: PLA MAX | C18: 79 | E18: 3622 | F18: 6 | G18: =$C18*$H$3*'ASTM D638-Probetas'!B$6 -> 4108 | H18: =$C18*$H$3*'ASTM D638-Probetas'!C$6 -> 1896 | I18: =$C18*$H$3*'ASTM D638-Probetas'!D$6 -> 10507 | J18: =F18/100*50 -> 3 | K18: =J18/1/50*7.62 -> 0.4572 | L18: =J18/10/50*7.62 -> 0.04572 | M18: =J18/100/50*7.62 -> 0.004572 | N18: =J18/5 -> 0.6 | O18: =J18/50 -> 0.06 | P18: =J18/500 -> 0.006 | Q18: =F18*50/100/100 -> 0.03 | R18: =50+J18 -> 53 | S18: =R18+$S$4 -> 63 | T18: =S18/$T$7 -> 0.0068837413 | U18: =IF(T18<Q18,"SI",IF(Q18=0,"SI",IF(T18>Q18,"NO"))) -> SI | V18: =Q18/T18 -> 4.3580952
B19: ABS | C19: 35 | D19: Tipo I | E19: 2480 | F19: 18 | G19: =$C19*$H$3*'ASTM D638-Probetas'!B$6 -> 1820 | H19: =$C19*$H$3*'ASTM D638-Probetas'!C$6 -> 840 | I19: =$C19*$H$3*'ASTM D638-Probetas'!D$6 -> 4655 | J19: =F19/100*50 -> 9 | K19: =J19/1/50*7.62 -> 1.3716 | L19: =J19/10/50*7.62 -> 0.13716 | M19: =J19/100/50*7.62 -> 0.013716 | N19: =J19/5 -> 1.8 | O19: =J19/50 -> 0.18 | P19: =J19/500 -> 0.018 | Q19: =F19*50/100/100 -> 0.09 | R19: =50+J19 -> 59 | S19: =R19+$S$4 -> 69 | T19: =S19/$T$7 -> 0.0075393357 | U19: =IF(T19<Q19,"SI",IF(Q19=0,"SI",IF(T19>Q19,"NO"))) -> SI | V19: =Q19/T19 -> 11.937391
B20: PETG | C20: 50 | F20: 130 | G20: =$C20*$H$3*'ASTM D638-Probetas'!B$6 -> 2600 | H20: =$C20*$H$3*'ASTM D638-Probetas'!C$6 -> 1200 | I20: =$C20*$H$3*'ASTM D638-Probetas'!D$6 -> 6650 | J20: =F20/100*50 -> 65 | K20: =J20/1/50*7.62 -> 9.906 | L20: =J20/10/50*7.62 -> 0.9906 | M20: =J20/100/50*7.62 -> 0.09906 | N20: =J20/5 -> 13 | O20: =J20/50 -> 1.3 | P20: =J20/500 -> 0.13 | Q20: =F20*50/100/100 -> 0.65 | R20: =50+J20 -> 115 | S20: =R20+$S$4 -> 125 | T20: =S20/$T$7 -> 0.013658217 | U20: =IF(T20<Q20,"SI",IF(Q20=0,"SI",IF(T20>Q20,"NO"))) -> SI | V20: =Q20/T20 -> 47.5904
B21: HIPS | C21: 23 | E21: 2000 | F21: 50 | G21: =$C21*$H$3*'ASTM D638-Probetas'!B$6 -> 1196 | H21: =$C21*$H$3*'ASTM D638-Probetas'!C$6 -> 552 | I21: =$C21*$H$3*'ASTM D638-Probetas'!D$6 -> 3059 | J21: =F21/100*50 -> 25 | K21: =J21/1/50*7.62 -> 3.81 | L21: =J21/10/50*7.62 -> 0.381 | M21: =J21/100/50*7.62 -> 0.0381 | N21: =J21/5 -> 5 | O21: =J21/50 -> 0.5 | P21: =J21/500 -> 0.05 | Q21: =F21*50/100/100 -> 0.25 | R21: =50+J21 -> 75 | S21: =R21+$S$4 -> 85 | T21: =S21/$T$7 -> 0.0092875874 | U21: =IF(T21<Q21,"SI",IF(Q21=0,"SI",IF(T21>Q21,"NO"))) -> SI | V21: =Q21/T21 -> 26.917647
B22: PC | C22: 50 | E22: 2350 | F22: 110 | G22: =$C22*$H$3*'ASTM D638-Probetas'!B$6 -> 2600 | H22: =$C22*$H$3*'ASTM D638-Probetas'!C$6 -> 1200 | I22: =$C22*$H$3*'ASTM D638-Probetas'!D$6 -> 6650 | J22: =F22/100*50 -> 55 | K22: =J22/1/50*7.62 -> 8.382 | L22: =J22/10/50*7.62 -> 0.8382 | M22: =J22/100/50*7.62 -> 0.08382 | N22: =J22/5 -> 11 | O22: =J22/50 -> 1.1 | P22: =J22/500 -> 0.11 | Q22: =F22*50/100/100 -> 0.55 | R22: =50+J22 -> 105 | S22: =R22+$S$4 -> 115 | T22: =S22/$T$7 -> 0.012565559 | U22: =IF(T22<Q22,"SI",IF(Q22=0,"SI",IF(T22>Q22,"NO"))) -> SI | V22: =Q22/T22 -> 43.770435
B23: PC/ABS | C23: 45 | F23: 100 | G23: =$C23*$H$3*'ASTM D638-Probetas'!B$6 -> 2340 | H23: =$C23*$H$3*'ASTM D638-Probetas'!C$6 -> 1080 | I23: =$C23*$H$3*'ASTM D638-Probetas'!D$6 -> 5985 | J23: =F23/100*50 -> 50 | K23: =J23/1/50*7.62 -> 7.62 | L23: =J23/10/50*7.62 -> 0.762 | M23: =J23/100/50*7.62 -> 0.0762 | N23: =J23/5 -> 10 | O23: =J23/50 -> 1 | P23: =J23/500 -> 0.1 | Q23: =F23*50/100/100 -> 0.5 | R23: =50+J23 -> 100 | S23: =R23+$S$4 -> 110 | T23: =S23/$T$7 -> 0.012019231 | U23: =IF(T23<Q23,"SI",IF(Q23=0,"SI",IF(T23>Q23,"NO"))) -> SI | V23: =Q23/T23 -> 41.6
A24: 3D System | B24: DuraFor ProX PA - Polvo | C24: 48 | D24: Tipo I | E24: 2100 | F24: 19 | G24: =$C24*$H$3*'ASTM D638-Probetas'!B$6 -> 2496 | H24: =$C24*$H$3*'ASTM D638-Probetas'!C$6 -> 1152 | I24: =$C24*$H$3*'ASTM D638-Probetas'!D$6 -> 6384 | J24: =F24/100*50 -> 9.5 | K24: =J24/1/50*7.62 -> 1.4478 | L24: =J24/10/50*7.62 -> 0.14478 | M24: =J24/100/50*7.62 -> 0.014478 | N24: =J24/5 -> 1.9 | O24: =J24/50 -> 0.19 | P24: =J24/500 -> 0.019 | Q24: =F24*50/100/100 -> 0.095 | R24: =50+J24 -> 59.5 | S24: =R24+$S$4 -> 69.5 | T24: =S24/$T$7 -> 0.0075939685 | U24: =IF(T24<Q24,"SI",IF(Q24=0,"SI",IF(T24>Q24,"NO"))) -> SI | V24: =Q24/T24 -> 12.509928
B25: Figure 4 TOUGH-BLK 20 | C25: 40 | E25: 1780 | F25: 36 | G25: =$C25*$H$3*'ASTM D638-Probetas'!B$6 -> 2080 | H25: =$C25*$H$3*'ASTM D638-Probetas'!C$6 -> 960 | I25: =$C25*$H$3*'ASTM D638-Probetas'!D$6 -> 5320 | J25: =F25/100*50 -> 18 | K25: =J25/1/50*7.62 -> 2.7432 | L25: =J25/10/50*7.62 -> 0.27432 | M25: =J25/100/50*7.62 -> 0.027432 | N25: =J25/5 -> 3.6 | O25: =J25/50 -> 0.36 | P25: =J25/500 -> 0.036 | Q25: =F25*50/100/100 -> 0.18 | R25: =50+J25 -> 68 | S25: =R25+$S$4 -> 78 | T25: =S25/$T$7 -> 0.0085227273 | U25: =IF(T25<Q25,"SI",IF(Q25=0,"SI",IF(T25>Q25,"NO"))) -> SI | V25: =Q25/T25 -> 21.12
B26: Figure 4 Gris Rígido - Resina | C26: 61 | E26: 2400 | F26: 30 | G26: =$C26*$H$3*'ASTM D638-Probetas'!B$6 -> 3172 | H26: =$C26*$H$3*'ASTM D638-Probetas'!C$6 -> 1464 | I26: =$C26*$H$3*'ASTM D638-Probetas'!D$6 -> 8113 | J26: =F26/100*50 -> 15 | K26: =J26/1/50*7.62 -> 2.286 | L26: =J26/10/50*7.62 -> 0.2286 | M26: =J26/100/50*7.62 -> 0.02286 | N26: =J26/5 -> 3 | O26: =J26/50 -> 0.3 | P26: =J26/500 -> 0.03 | Q26: =F26*50/100/100 -> 0.15 | R26: =50+J26 -> 65 | S26: =R26+$S$4 -> 75 | T26: =S26/$T$7 -> 0.0081949301 | U26: =IF(T26<Q26,"SI",IF(Q26=0,"SI",IF(T26>Q26,"NO"))) -> SI | V26: =Q26/T26 -> 18.304
B27: Figure 4 TOUGH-GRY 15 - Resina | C27: 48 | E27: 2120 | F27: 35 | G27: =$C27*$H$3*'ASTM D638-Probetas'!B$6 -> 2496 | H27: =$C27*$H$3*'ASTM D638-Probetas'!C$6 -> 1152 | I27: =$C27*$H$3*'ASTM D638-Probetas'!D$6 -> 6384 | J27: =F27/100*50 -> 17.5 | K27: =J27/1/50*7.62 -> 2.667 | L27: =J27/10/50*7.62 -> 0.2667 | M27: =J27/100/50*7.62 -> 0.02667 | N27: =J27/5 -> 3.5 | O27: =J27/50 -> 0.35 | P27: =J27/500 -> 0.035 | Q27: =F27*50/100/100 -> 0.175 | R27: =50+J27 -> 67.5 | S27: =R27+$S$4 -> 77.5 | T27: =S27/$T$7 -> 0.0084680944 | U27: =IF(T27<Q27,"SI",IF(Q27=0,"SI",IF(T27>Q27,"NO"))) -> SI | V27: =Q27/T27 -> 20.665806
B28: Accura 60 - Resina | C28: 68 | E28: 3100 | F28: 13 | G28: =$C28*$H$3*'ASTM D638-Probetas'!B$6 -> 3536 | H28: =$C28*$H$3*'ASTM D638-Probetas'!C$6 -> 1632 | I28: =$C28*$H$3*'ASTM D638-Probetas'!D$6 -> 9044 | J28: =F28/100*50 -> 6.5 | K28: =J28/1/50*7.62 -> 0.9906 | L28: =J28/10/50*7.62 -> 0.09906 | M28: =J28/100/50*7.62 -> 0.009906 | N28: =J28/5 -> 1.3 | O28: =J28/50 -> 0.13 | P28: =J28/500 -> 0.013 | Q28: =F28*50/100/100 -> 0.065 | R28: =50+J28 -> 56.5 | S28: =R28+$S$4 -> 66.5 | T28: =S28/$T$7 -> 0.0072661713 | U28: =IF(T28<Q28,"SI",IF(Q28=0,"SI",IF(T28>Q28,"NO"))) -> SI | V28: =Q28/T28 -> 8.9455639
B29: Accura ClearVue - Resina | C29: 53 | E29: 2640 | F29: 15 | G29: =$C29*$H$3*'ASTM D638-Probetas'!B$6 -> 2756 | H29: =$C29*$H$3*'ASTM D638-Probetas'!C$6 -> 1272 | I29: =$C29*$H$3*'ASTM D638-Probetas'!D$6 -> 7049 | J29: =F29/100*50 -> 7.5 | K29: =J29/1/50*7.62 -> 1.143 | L29: =J29/10/50*7.62 -> 0.1143 | M29: =J29/100/50*7.62 -> 0.01143 | N29: =J29/5 -> 1.5 | O29: =J29/50 -> 0.15 | P29: =J29/500 -> 0.015 | Q29: =F29*50/100/100 -> 0.075 | R29: =50+J29 -> 57.5 | S29: =R29+$S$4 -> 67.5 | T29: =S29/$T$7 -> 0.0073754371 | U29: =IF(T29<Q29,"SI",IF(Q29=0,"SI",IF(T29>Q29,"NO"))) -> SI | V29: =Q29/T29 -> 10.168889
B30: Accura Fidelity - Resina | C30: 65 | E30: 2790 | F30: 5 | G30: =$C30*$H$3*'ASTM D638-Probetas'!B$6 -> 3380 | H30: =$C30*$H$3*'ASTM D638-Probetas'!C$6 -> 1560 | I30: =$C30*$H$3*'ASTM D638-Probetas'!D$6 -> 8645 | J30: =F30/100*50 -> 2.5 | K30: =J30/1/50*7.62 -> 0.381 | L30: =J30/10/50*7.62 -> 0.0381 | M30: =J30/100/50*7.62 -> 0.00381 | N30: =J30/5 -> 0.5 | O30: =J30/50 -> 0.05 | P30: =J30/500 -> 0.005 | Q30: =F30*50/100/100 -> 0.025 | R30: =50+J30 -> 52.5 | S30: =R30+$S$4 -> 62.5 | T30: =S30/$T$7 -> 0.0068291084 | U30: =IF(T30<Q30,"SI",IF(Q30=0,"SI",IF(T30>Q30,"NO"))) -> SI | V30: =Q30/T30 -> 3.6608
B31: Accura AMX Durable Natural - Resina | C31: 32 | D31: Tipo IV | E31: 1000 | F31: 80 | G31: =$C31*$H$3*'ASTM D638-Probetas'!B$6 -> 1664 | H31: =$C31*$H$3*'ASTM D638-Probetas'!C$6 -> 768 | I31: =$C31*$H$3*'ASTM D638-Probetas'!D$6 -> 4256 | J31: =F31/100*50 -> 40 | K31: =J31/1/50*7.62 -> 6.096 | L31: =J31/10/50*7.62 -> 0.6096 | M31: =J31/100/50*7.62 -> 0.06096 | N31: =J31/5 -> 8 | O31: =J31/50 -> 0.8 | P31: =J31/500 -> 0.08 | Q31: =F31*50/100/100 -> 0.4 | R31: =50+J31 -> 90 | S31: =R31+$S$4 -> 100 | T31: =S31/$T$7 -> 0.010926573 | U31: =IF(T31<Q31,"SI",IF(Q31=0,"SI",IF(T31>Q31,"NO"))) -> SI | V31: =Q31/T31 -> 36.608
B32: Accura Composite PIV - Resina | C32: 72 | D32: Tipo IV | E32: 9300 | F32: 1.2 | G32: =$C32*$H$3*'ASTM D638-Probetas'!B$6 -> 3744 | H32: =$C32*$H$3*'ASTM D638-Probetas'!C$6 -> 1728 | I32: =$C32*$H$3*'ASTM D638-Probetas'!D$6 -> 9576 | J32: =F32/100*50 -> 0.6 | K32: =J32/1/50*7.62 -> 0.09144 | L32: =J32/10/50*7.62 -> 0.009144 | M32: =J32/100/50*7.62 -> 0.0009144 | N32: =J32/5 -> 0.12 | O32: =J32/50 -> 0.012 | P32: =J32/500 -> 0.0012 | Q32: =F32*50/100/100 -> 0.006 | R32: =50+J32 -> 50.6 | S32: =R32+$S$4 -> 60.6 | T32: =S32/$T$7 -> 0.0066215035 | U32: =IF(T32<Q32,"SI",IF(Q32=0,"SI",IF(T32>Q32,"NO"))) -> NO | V32: =Q32/T32 -> 0.90613861
B33: DuraForm FR1200 - Resina | C33: 41 | E33: 2040 | F33: 5.9 | G33: =$C33*$H$3*'ASTM D638-Probetas'!B$6 -> 2132 | H33: =$C33*$H$3*'ASTM D638-Probetas'!C$6 -> 984 | I33: =$C33*$H$3*'ASTM D638-Probetas'!D$6 -> 5453 | J33: =F33/100*50 -> 2.95 | K33: =J33/1/50*7.62 -> 0.44958 | L33: =J33/10/50*7.62 -> 0.044958 | M33: =J33/100/50*7.62 -> 0.0044958 | N33: =J33/5 -> 0.59 | O33: =J33/50 -> 0.059 | P33: =J33/500 -> 0.0059 | Q33: =F33*50/100/100 -> 0.0295 | R33: =50+J33 -> 52.95 | S33: =R33+$S$4 -> 62.95 | T33: =S33/$T$7 -> 0.006878278 | U33: =IF(T33<Q33,"SI",IF(Q33=0,"SI",IF(T33>Q33,"NO"))) -> SI | V33: =Q33/T33 -> 4.2888642
B34: DuraForm® PA Plastic - Resina | C34: 43 | E34: 1586 | F34: 14 | G34: =$C34*$H$3*'ASTM D638-Probetas'!B$6 -> 2236 | H34: =$C34*$H$3*'ASTM D638-Probetas'!C$6 -> 1032 | I34: =$C34*$H$3*'ASTM D638-Probetas'!D$6 -> 5719 | J34: =F34/100*50 -> 7 | K34: =J34/1/50*7.62 -> 1.0668 | L34: =J34/10/50*7.62 -> 0.10668 | M34: =J34/100/50*7.62 -> 0.010668 | N34: =J34/5 -> 1.4 | O34: =J34/50 -> 0.14 | P34: =J34/500 -> 0.014 | Q34: =F34*50/100/100 -> 0.07 | R34: =50+J34 -> 57 | S34: =R34+$S$4 -> 67 | T34: =S34/$T$7 -> 0.0073208042 | U34: =IF(T34<Q34,"SI",IF(Q34=0,"SI",IF(T34>Q34,"NO"))) -> SI | V34: =Q34/T34 -> 9.561791
B35: Duraform GF | C35: 27 | E35: 4068 | F35: 1.4 | G35: =$C35*$H$3*'ASTM D638-Probetas'!B$6 -> 1404 | H35: =$C35*$H$3*'ASTM D638-Probetas'!C$6 -> 648 | I35: =$C35*$H$3*'ASTM D638-Probetas'!D$6 -> 3591 | J35: =F35/100*50 -> 0.7 | K35: =J35/1/50*7.62 -> 0.10668 | L35: =J35/10/50*7.62 -> 0.010668 | M35: =J35/100/50*7.62 -> 0.0010668 | N35: =J35/5 -> 0.14 | O35: =J35/50 -> 0.014 | P35: =J35/500 -> 0.0014 | Q35: =F35*50/100/100 -> 0.007 | R35: =50+J35 -> 50.7 | S35: =R35+$S$4 -> 60.7 | T35: =S35/$T$7 -> 0.0066324301 | U35: =IF(T35<Q35,"SI",IF(Q35=0,"SI",IF(T35>Q35,"NO"))) -> SI | V35: =Q35/T35 -> 1.0554201
A36: Stratasys | B36: Nylon 12 | C36: 32 | D36: Tipo I | E36: 1138 | F36: 30 | G36: =$C36*$H$3*'ASTM D638-Probetas'!B$6 -> 1664 | H36: =$C36*$H$3*'ASTM D638-Probetas'!C$6 -> 768 | I36: =$C36*$H$3*'ASTM D638-Probetas'!D$6 -> 4256 | J36: =F36/100*50 -> 15 | K36: =J36/1/50*7.62 -> 2.286 | L36: =J36/10/50*7.62 -> 0.2286 | M36: =J36/100/50*7.62 -> 0.02286 | N36: =J36/5 -> 3 | O36: =J36/50 -> 0.3 | P36: =J36/500 -> 0.03 | Q36: =F36*50/100/100 -> 0.15 | R36: =50+J36 -> 65 | S36: =R36+$S$4 -> 75 | T36: =S36/$T$7 -> 0.0081949301 | U36: =IF(T36<Q36,"SI",IF(Q36=0,"SI",IF(T36>Q36,"NO"))) -> SI | V36: =Q36/T36 -> 18.304
B37: Nylon 12 CF | C37: 75.6 | D37: Tipo I | E37: 7515 | F37: 1.9 | G37: =$C37*$H$3*'ASTM D638-Probetas'!B$6 -> 3931.2 | H37: =$C37*$H$3*'ASTM D638-Probetas'!C$6 -> 1814.4 | I37: =$C37*$H$3*'ASTM D638-Probetas'!D$6 -> 10054.8 | J37: =F37/100*50 -> 0.95 | K37: =J37/1/50*7.62 -> 0.14478 | L37: =J37/10/50*7.62 -> 0.014478 | M37: =J37/100/50*7.62 -> 0.0014478 | N37: =J37/5 -> 0.19 | O37: =J37/50 -> 0.019 | P37: =J37/500 -> 0.0019 | Q37: =F37*50/100/100 -> 0.0095 | R37: =50+J37 -> 50.95 | S37: =R37+$S$4 -> 60.95 | T37: =S37/$T$7 -> 0.0066597465 | U37: =IF(T37<Q37,"SI",IF(Q37=0,"SI",IF(T37>Q37,"NO"))) -> SI | V37: =Q37/T37 -> 1.4264807
B38: Nylon 12 CF | C38: 83.5 | D38: Tipo I | E38: 9460 | F38: 2.4 | G38: =$C38*$H$3*'ASTM D638-Probetas'!B$6 -> 4342 | H38: =$C38*$H$3*'ASTM D638-Probetas'!C$6 -> 2004 | I38: =$C38*$H$3*'ASTM D638-Probetas'!D$6 -> 11105.5 | J38: =F38/100*50 -> 1.2 | K38: =J38/1/50*7.62 -> 0.18288 | L38: =J38/10/50*7.62 -> 0.018288 | M38: =J38/100/50*7.62 -> 0.0018288 | N38: =J38/5 -> 0.24 | O38: =J38/50 -> 0.024 | P38: =J38/500 -> 0.0024 | Q38: =F38*50/100/100 -> 0.012 | R38: =50+J38 -> 51.2 | S38: =R38+$S$4 -> 61.2 | T38: =S38/$T$7 -> 0.0066870629 | U38: =IF(T38<Q38,"SI",IF(Q38=0,"SI",IF(T38>Q38,"NO"))) -> SI | V38: =Q38/T38 -> 1.7945098
B39: PC | C39: 57 | D39: Tipo I | E39: 1944 | F39: 4.8 | G39: =$C39*$H$3*'ASTM D638-Probetas'!B$6 -> 2964 | H39: =$C39*$H$3*'ASTM D638-Probetas'!C$6 -> 1368 | I39: =$C39*$H$3*'ASTM D638-Probetas'!D$6 -> 7581 | J39: =F39/100*50 -> 2.4 | K39: =J39/1/50*7.62 -> 0.36576 | L39: =J39/10/50*7.62 -> 0.036576 | M39: =J39/100/50*7.62 -> 0.0036576 | N39: =J39/5 -> 0.48 | O39: =J39/50 -> 0.048 | P39: =J39/500 -> 0.0048 | Q39: =F39*50/100/100 -> 0.024 | R39: =50+J39 -> 52.4 | S39: =R39+$S$4 -> 62.4 | T39: =S39/$T$7 -> 0.0068181818 | U39: =IF(T39<Q39,"SI",IF(Q39=0,"SI",IF(T39>Q39,"NO"))) -> SI | V39: =Q39/T39 -> 3.52
B40: ULTEM 9085 resin | C40: 70 | D40: Tipo I | E40: 2510 | F40: 5.4 | G40: =$C40*$H$3*'ASTM D638-Probetas'!B$6 -> 3640 | H40: =$C40*$H$3*'ASTM D638-Probetas'!C$6 -> 1680 | I40: =$C40*$H$3*'ASTM D638-Probetas'!D$6 -> 9310 | J40: =F40/100*50 -> 2.7 | K40: =J40/1/50*7.62 -> 0.41148 | L40: =J40/10/50*7.62 -> 0.041148 | M40: =J40/100/50*7.62 -> 0.0041148 | N40: =J40/5 -> 0.54 | O40: =J40/50 -> 0.054 | P40: =J40/500 -> 0.0054 | Q40: =F40*50/100/100 -> 0.027 | R40: =50+J40 -> 52.7 | S40: =R40+$S$4 -> 62.7 | T40: =S40/$T$7 -> 0.0068509615 | U40: =IF(T40<Q40,"SI",IF(Q40=0,"SI",IF(T40>Q40,"NO"))) -> SI | V40: =Q40/T40 -> 3.9410526
A41: MatterHackers | B41: NylonG (fibra de vidrio) | C41: 95 | E41: 4000 | G41: =$C41*$H$3*'ASTM D638-Probetas'!B$6 -> 4940 | H41: =$C41*$H$3*'ASTM D638-Probetas'!C$6 -> 2280 | I41: =$C41*$H$3*'ASTM D638-Probetas'!D$6 -> 12635 | J41: =F41/100*50 -> 0 | K41: =J41/1/50*7.62 -> 0 | L41: =J41/10/50*7.62 -> 0 | M41: =J41/100/50*7.62 -> 0 | N41: =J41/5 -> 0 | O41: =J41/50 -> 0 | P41: =J41/500 -> 0 | Q41: =F41*50/100/100 -> 0 | R41: =50+J41 -> 50 | S41: =R41+$S$4 -> 60 | T41: =S41/$T$7 -> 0.0065559441 | U41: =IF(T41<Q41,"SI",IF(Q41=0,"SI",IF(T41>Q41,"NO"))) -> SI | V41: =Q41/T41 -> 0
...
